Workbook
Name item_1.1: [1]Datos!$C$2
Name Item1.2: [1]Datos!$C$3

Sheet Datos
A1: id | B1: descripcion | C1: cantidad | D1: reglas_validacion_afectadas
A2: 1 | B2: Registros de Datos_Predio donde el digito 22 de Datos_Predio.Numero Predial sea igual a "0" o "2" o "3" o "4" o "7" y con Datos Predio.Estado = Activo y Datos Predio.Etapa = "CONTROL_CALIDAD_GENERAL" o "CONTROL_CALIDAD_GRUPO" | D2: 1.1
A3: 2 | B3: Registros de Datos Predio donde Datos Predio.Condicion Predio Tipo = "Matriz" con Datos Predio.Estado = Activo y Datos Predio.Etapa = "CONTROL_CALIDAD_GENERAL" o "CONTROL_CALIDAD_GRUPO" | D3: 1.4
A4: 3 | B4: Registros de Datos Predio donde Datos Predio.Condicion Predio Tipo es PH.Unidad_Predial con Datos Predio.Estado = Activo y Datos Predio.Etapa = "CONTROL_CALIDAD_GENERAL" o "CONTROL_CALIDAD_GRUPO" | D4: 1.5
A5: 4 | B5: Registros de Datos Predio Datos donde Datos Predio.Condicion Predio Tipo = Condominio.Matriz con Datos Predio.Estado = Activo y Datos Predio.Etapa = "CONTROL_CALIDAD_GENERAL" o "CONTROL_CALIDAD_GRUPO" | D5: 1.6
A6: 5 | B6: Registros de Datos Predio donde Predio.Condicion Predio Tipo = Condominio.Unidad Predial con Datos Predio.Estado = Activo y Datos Predio.Etapa = "CONTROL_CALIDAD_GENERAL" o "CONTROL_CALIDAD_GRUPO" | D6: 1.7
A7: 6 | B7: Registros de Datos_Predio donde el digito 22 de Datos_Predio.Numero Predial sea igual a "1" o "5" o "6" con Datos Predio.Estado = Activo y Datos Predio.Etapa = "CONTROL_CALIDAD_GENERAL" o "CONTROL_CALIDAD_GRUPO" | D7: 1.8
A8: 7 | B8: Todos los registros de Datos Predio-Derecho en estado Activo con Datos Predio.Estado = Activo y Datos Predio.Etapa = "CONTROL_CALIDAD_GENERAL" o "CONTROL_CALIDAD_GRUPO" | D8: 1.9 , 1.10 , 2,4
A9: 8 | B9: Todos los registros de Datos Predio en estado Activo con Datos Predio.Estado = Activo y Datos Predio.Etapa = "CONTROL_CALIDAD_GENERAL" o "CONTROL_CALIDAD_GRUPO" | D9: 1.12 , 1.23, 2,38
A10: 9 | B10: Todos los registros de Datos Predios con Datos Predio.Matricula diligenciado, que en Datos Predio.Estado = Activo y Datos Predio.Etapa = "CONTROL_CALIDAD_GENERAL" o "CONTROL_CALIDAD_GRUPO" | D10: 1.13 , 1.14 , 2,1, 2.16
A11: 10 | B11: Registros de Datos Predio.Circulo Registral diligenciado con Datos Predio.Estado = Activo y Datos Predio.Etapa = "CONTROL_CALIDAD_GENERAL" o "CONTROL_CALIDAD_GRUPO" | D11: 1.15
A12: 11 | B12: Registros de Datos Predio.Destino = R,S,T con Datos Predio.Estado = Activo y Datos Predio.Etapa = "CONTROL_CALIDAD_GENERAL" o "CONTROL_CALIDAD_GRUPO" | D12: 1.18
A13: 12 | B13: Registros de Datos Predio.Destino = A, B, C, F, G, I, J, X con Datos Predio.Estado = Activo y Datos Predio.Etapa = "CONTROL_CALIDAD_GENERAL" o "CONTROL_CALIDAD_GRUPO" | D13: 1.19
A14: 13 | B14: Registros de Datos Predio.Destino = 'U','L','N','M','Z','O','AA','AC','W','R','S' con Datos Predio.Estado = Activo y Datos Predio.Etapa = "CONTROL_CALIDAD_GENERAL" o "CONTROL_CALIDAD_GRUPO" | D14: 1.21
A15: 14 | B15: Registros de Datos Predio.Tiene FMI = No con Datos Predio.Estado = Activo y Datos Predio.Etapa = "CONTROL_CALIDAD_GENERAL" o "CONTROL_CALIDAD_GRUPO" | D15: 1.22
A16: 15 | B16: Registros de Datos Predio.Condicion Predio Tipo = NPH, Matriz ó Condominio.Matriz, Condominio.Unidad_Predial con Datos Predio.Estado = Activo y Datos Predio.Etapa = "CONTROL_CALIDAD_GENERAL" o "CONTROL_CALIDAD_GRUPO" | D16: 1.24
A17: 16 | B17: Registros de Datos Contacto con Datos Contacto.Primer Nombre y Datos Contacto.Primer Apellido diligenciados con Datos Predio.Estado = Activo y Datos Predio.Etapa = "CONTROL_CALIDAD_GENERAL" o "CONTROL_CALIDAD_GRUPO" | D17: 1.49
A18: 17 | B18: Registros de Datos Contacto con Datos Contacto.Numero Documento diligenciados y con estado Activo con Datos Predio.Estado = Activo y Datos Predio.Etapa = "CONTROL_CALIDAD_GENERAL" o "CONTROL_CALIDAD_GRUPO" | D18: 1.50
A19: 18 | B19: Todos los registros de Datos Contacto con estado Activo con Datos Predio.Estado = Activo y Datos Predio.Etapa = "CONTROL_CALIDAD_GENERAL" o "CONTROL_CALIDAD_GRUPO" | D19: 1.51 , 1.55
A20: 19 | B20: Registros de Datos Contacto con Datos Contacto.Celular diligenciados y con estado Activo con Datos Predio.Estado = Activo y Datos Predio.Etapa = "CONTROL_CALIDAD_GENERAL" o "CONTROL_CALIDAD_GRUPO" | D20: 1.52
A21: 20 | B21: Registros de Datos Contacto con Datos Contacto.Correo Electronico diligenciados con Datos Predio.Estado = Activo y Datos Predio.Etapa = "CONTROL_CALIDAD_GENERAL" o "CONTROL_CALIDAD_GRUPO" | D21: 1.53
A22: 21 | B22: Registros de Datos Contacto con Datos Contacto.Autoriza Notificacion = "SI" con Datos Predio.Estado = Activo y Datos Predio.Etapa = "CONTROL_CALIDAD_GENERAL" o "CONTROL_CALIDAD_GRUPO" | D22: 1.54
A23: 22 | B23: Registros de Datos Contacto con Datos Contacto.Direccion diligenciado con Datos Predio.Estado = Activo y Datos Predio.Etapa = "CONTROL_CALIDAD_GENERAL" o "CONTROL_CALIDAD_GRUPO" | D23: 1.56
A24: 23 | B24: Registros de Datos Predio con Datos Predio.Condicion Predio Tipo = PH.Unidad Predial con Datos Predio.Estado = Activo y Datos Predio.Etapa = "CONTROL_CALIDAD_GENERAL" o "CONTROL_CALIDAD_GRUPO" | D24: 1.60
A25: 24 | B25: Registros de Datos_Predio donde el digito 22 de Datos_Predio.Numero Predial sea difrente a "2" y con Datos Predio.Estado = Activo y Datos Predio.Etapa = "CONTROL_CALIDAD_GENERAL" o "CONTROL_CALIDAD_GRUPO" | D25: 2.5
A26: 25 | B26: Registros con Datos Predio.Tipo Predio = “Privado” y Datos Predio - Derecho.Tipo Derecho = “Dominio” con Datos Predio.Estado = Activo y Datos Predio.Etapa = "CONTROL_CALIDAD_GENERAL" o "CONTROL_CALIDAD_GRUPO" | D26: 2.6
A27: 26 | B27: Datos Predio - Derecho.Tipo Derecho = “Posesion” con Datos Predio.Estado = Activo y Datos Predio.Etapa = "CONTROL_CALIDAD_GENERAL" o "CONTROL_CALIDAD_GRUPO" | D27: 2.7
A28: 27 | B28: Datos Predio.Tipo Predio = “Privado” con Datos Predio.Estado = Activo y Datos Predio.Etapa = "CONTROL_CALIDAD_GENERAL" o "CONTROL_CALIDAD_GRUPO" | D28: 2.8
A29: 28 | B29: Datos Predio.Tipo Predio = “Publico.Baldio” ó “Publico.Fiscal” ó “Publico.Patrimonial” ó “Publico.Uso_Publico” con Datos Predio.Estado = Activo y Datos Predio.Etapa = "CONTROL_CALIDAD_GENERAL" o "CONTROL_CALIDAD_GRUPO" | D29: 2.9
A30: 29 | B30: Datos Predio.Tipo Predio = “Publico.Baldio” y Datos Predio - Derecho.Tipo Derecho = “Dominio” con Datos Predio.Estado = Activo y Datos Predio.Etapa = "CONTROL_CALIDAD_GENERAL" o "CONTROL_CALIDAD_GRUPO" | D30: 2.10, 2.13
A31: 30 | B31: Datos Predio.Tipo Predio = Territorio_Colectivo con Datos Predio.Estado = Activo y Datos Predio.Etapa = "CONTROL_CALIDAD_GENERAL" o "CONTROL_CALIDAD_GRUPO" | D31: 2.11
A32: 31 | B32: Datos Predio.Tipo Predio = “Publico.Baldio” y Datos Predio - Derecho.Tipo Derecho = “Ocupacion” con Datos Predio.Estado = Activo y Datos Predio.Etapa = "CONTROL_CALIDAD_GENERAL" o "CONTROL_CALIDAD_GRUPO" | D32: 2.12
A33: 32 | B33: Todos los registros de Datos Predios con longitud de Datos Predio.Matricula > 7 que en Datos Predio.Estado = Activo y Datos Predio.Etapa = "CONTROL_CALIDAD_GENERAL" o "CONTROL_CALIDAD_GRUPO" | D33: 2.17
A34: 33 | B34: Registros de Datos Predio.Tiene FMI = Si con Datos Predio.Estado = Activo y Datos Predio.Etapa = "CONTROL_CALIDAD_GENERAL" o "CONTROL_CALIDAD_GRUPO" | D34: 2.18
A35: 34 | B35: Registros de Datos Propietarios donde Datos Propietarios.Tipo Persona = “JURIDICA” con Datos Predio.Estado = Activo y Datos Predio.Etapa = "CONTROL_CALIDAD_GENERAL" o "CONTROL_CALIDAD_GRUPO" | D35: 2.20 , 2.25, 2.27
A36: 35 | B36: Registros de Datos Propietarios donde Datos Propietarios.Tipo Persona = “NATURAL” con Datos Predio.Estado = Activo y Datos Predio.Etapa = "CONTROL_CALIDAD_GENERAL" o "CONTROL_CALIDAD_GRUPO" | D36: 2.21 , 2.24 , 2.26, 2.29
A37: 36 | B37: Registros de Datos Propietarios donde Datos Propietarios. Tipo documento = “CC” ó “CE” ó "P" ó “TI” ó “RC” con Datos Predio.Estado = Activo y Datos Predio.Etapa = "CONTROL_CALIDAD_GENERAL" o "CONTROL_CALIDAD_GRUPO" | D37: 2.22
A38: 37 | B38: Registros de Datos Propietarios donde Propietarios. Tipo documento = “NIT” con Datos Predio.Estado = Activo y Datos Predio.Etapa = "CONTROL_CALIDAD_GENERAL" o "CONTROL_CALIDAD_GRUPO" | D38: 2.23
A39: 38 | B39: Todos los registros de Datos Propietarios con Datos Predio.Estado = Activo y Datos Predio.Etapa = "CONTROL_CALIDAD_GENERAL" o "CONTROL_CALIDAD_GRUPO" | D39: 2,28 , 2,32, 2,33, 2.37, 2,39, 2,40
A40: 39 | B40: Registros de Datos Propietarios donde Datos Propietario.Grupo Interesado = "Grupo_Mixto" con Datos Predio.Estado = Activo y Datos Predio.Etapa = "CONTROL_CALIDAD_GENERAL" o "CONTROL_CALIDAD_GRUPO" | D40: 2.30
...

Sheet 0. Estructura
A1: CONSISTENCIA LOGICA - BASE CATASTRAL DIRECCIÓN DE GESTIÓN CATASTRAL
B3: DEPARTAMENTO: | C3: NOMBRE CONTROL DE CALIDAD QUE ELABORÓ: | H3: Firma:
B4: MUNICIPIO: | C4: NOMBRE CONTROL DE CALIDAD QUE REVISÓ: | H4: Firma:
C5: FECHA DE VALIDACION: | F5: AAAA/MM/DD
A6: ID | B6: ELEMENTO EVALUADO | F6: Situaciones encontradas | H6: Observaciones
A7: 1 | B7: Ningun campo de tipo "String" debe contener caracteres especiales | F7: 0
A8: 2 | B8: Ningun campo de la base de datos puede contener "pipes" (|) | F8: 0
A9: TOTAL | F9: =+F7+F8 -> 0

Sheet 1. Administrativo
A1: CONSISTENCIA LOGICA - BASE CATASTRAL DIRECCIÓN DE GESTIÓN CATASTRAL
B3: DEPARTAMENTO: | C3: NOMBRE CONTROL DE CALIDAD QUE ELABORÓ: | H3: Firma:
B4: MUNICIPIO: | C4: NOMBRE CONTROL DE CALIDAD QUE REVISÓ: | H4: Firma:
C5: FECHA DE VALIDACION: | F5: AAAA/MM/DD
A6: ID | B6: ELEMENTO EVALUADO | C6: Cantidad de Items | D6: Situaciones encontradas | E6: Cantidad Excepciones | F6: Cantidad Errores | G6: % Calidad Item | H6: Observaciones
A7: 1.1 | B7: Los campos 22 a 30 del número predial deben corresponder con la condición de propiedad asignada. No deben existir predios con numeros prediales repetidos | C7: =Datos!C2 -> 0 | D7: 0 | E7: 0 | F7: =D7-E7 -> 0 | G7: =1-(F7)/C7 -> #DIV/0!
A8: 1.4 | B8: Los campos 22 a 30 del número predial para predios con condición de propiedad PH matriz se estandarizan como "900000000" | C8: =Datos!C3 -> 0 | D8: 0 | E8: 0 | F8: =D8-E8 -> 0 | G8: =1-(F8)/C8 -> #DIV/0!
A9: 1.5 | B9: El campo 22 del número predial para predios con condición de propiedad PH Unidad predial se estandariza como "9", los campo 23 a 24 no puede ser "00", los campo 25 a 26 no puede ser "00" y los campos 27 a 30 no pueden ser "0000" | C9: =Datos!C4 -> 0 | D9: 0 | E9: 0 | F9: =D9-E9 -> 0 | G9: =1-(F9)/C9 -> #DIV/0!
A10: 1.6 | B10: Los campos 22 a 30 del número predial para predios con condición de propiedad Condominio matriz se estandarizan como "800000000" | C10: =Datos!C5 -> 0 | D10: 0 | E10: 0 | F10: =D10-E10 -> 0 | G10: =1-(F10)/C10 -> #DIV/0!
A11: 1.7 | B11: El campos 22 al 26 del número predial para predios con condición de propiedad Condominio.Unidad_predial se estandariza como "80000" y los campos del 27 al 30 deben ser diferente a "0000" | C11: =Datos!C6 -> 0 | D11: 0 | E11: 0 | F11: =D11-E11 -> 0 | G11: =1-(F11)/C11 -> #DIV/0!
A12: 1.8 | B12: El campo 22 del número predial debe ser diferente a "1", "5" y "6". | C12: =Datos!C7 -> 0 | D12: 0 | E12: 0 | F12: =D12-E12 -> 0 | G12: =1-(F12)/C12 -> #DIV/0!
A13: 1.9 | B13: Los campos 1 y 2 de número predial debe corresponder al valor diligenciado en Departamento | C13: =Datos!C8 -> 0 | D13: 0 | E13: 0 | F13: =D13-E13 -> 0 | G13: =1-(F13)/C13 -> #DIV/0!
A14: 1.10 | B14: Los campos 3 a 5 de número predial debe corresponder al valor diligenciado en Municipio | C14: =Datos!C8 -> 0 | D14: 0 | E14: 0 | F14: =D14-E14 -> 0 | G14: =1-(F14)/C14 -> #DIV/0!
A15: 1.12 | B15: Si en el dato Tiene FMI y se ha marcado Si (Verdadero) debe tener registrado número de oficina de registro (circulo registral) y folio matricula inmobiliaria Si en el dato no Tiene FMI y se ha marcado NO (false) no debe tener registrado número de oficina de registro (circulo registral) y folio matricula inmobiliaria | C15: =Datos!C9 -> 0 | D15: 0 | E15: 0 | F15: =D15-E15 -> 0 | G15: =1-(F15)/C15 -> #DIV/0!
A16: 1.13 | B16: El valor de Matricula_inmobiliaria no puede estar relacionado a más de un numero predial (FMI duplicados, pueden existir excepciones) | C16: =Datos!C10 -> 0 | F16: =D16-E16 -> 0 | G16: =1-(F16)/C16 -> #DIV/0!
A17: 1.14 | B17: El valor registrado en Matricula_inmobiliaria debe ser lógico (codificación completa) y no contener ningún carácter alfabético | C17: =Datos!C10 -> 0 | D17: 0 | E17: 0 | F17: =D17-E17 -> 0 | G17: =1-(F17)/C17 -> #DIV/0!
A18: 1.15 | B18: El Codigo_ORIP asignado a cada una de las Matricula_inmobiliaria debe estar asociado al dato del círculo registral | C18: =Datos!C11 -> 0 | D18: 0 | E18: 0 | F18: =D18-E18 -> 0 | G18: =1-(F18)/C18 -> #DIV/0!
A19: 1.18 | B19: Para predios con destinación económica: Lote urbanizado no construido, no se deben relacionar ni ubicar espacialmente construcciones | C19: =Datos!C12 -> 0 | D19: 0 | E19: 0 | F19: =D19-E19 -> 0 | G19: =1-(F19)/C19 -> #DIV/0!
A20: 1.19 | B20: Para predios con destinación económica: Comercial, educativo, habitacional, industrial, institucional y salubridad debe relacionar espacialmente al menos una construcción | C20: =Datos!C13 -> 0 | D20: 0 | E20: 0 | F20: =D20-E20 -> 0 | G20: =1-(F20)/C20 -> #DIV/0!
A21: 1.21 | B21: Los predios con destinación económica "Acuicola, Agricola, Agroindustrial, Agropecuario, Agroforestal, Forestal, Infraestructura asociada producción agropecuaria, Infraestructura de saneamiento básico, Minería Hidrocarburos, Pecuario deben estar relacionados a numeros prediales rurales; Por otra parte, los predios con destinación económica "Lote urbanizable no urbanizado y Lote urbanizado no construido" deben estar relacionados a numeros prediales urbanos. | C21: =Datos!C14 -> 0 | D21: 0 | E21: 0 | F21: =D21-E21 -> 0 | G21: =1-(F21)/C21 -> #DIV/0!
A22: 1.22 | B22: Si el predio tiene el campo "Tiene_FMI" diligenciado como "No" entonces el campo "Area_Registral" debe ser 0 | C22: =Datos!C15 -> 0 | D22: 0 | E22: 0 | F22: =D22-E22 -> 0 | G22: =1-(F22)/C22 -> #DIV/0!
A23: 1.23 | B23: Si el campo "tiene_area_registral" esta diligenciado como "Si" , entonces el campo "area registral" no debe estar en 0. Si el campo "tiene_area_registral" esta diligenciado como "No" , entonces el campo "area registral" debe estar en 0. | C23: =Datos!C9 -> 0 | D23: 0 | E23: 0 | F23: =D23-E23 -> 0 | G23: =1-(F23)/C23 -> #DIV/0!
A24: 1.24 | B24: Los predios asociados a condiciones de propiedad NPH ó PH.matriz o Condominio.Matriz o Condominio.Unidad_Predial o Vía o Bien_Uso_Publico o Parque Cementerio, deben estar representados en la capa de terreno excepto los que tienen asociado en novedades del levantamiento Cancelación. De igual forma todos los terrenos deben tener asociados a un registro de Datos_Predio condiciones de propiedad NPH o PH.matriz o Condominio.Matriz o Condominio.Unidad_Predial o Vía o Bien_Uso_Publico sin novedad de Cancelación. | C24: =Datos!C16 -> 0 | D24: 0 | E24: 0 | F24: =D24-E24 -> 0 | G24: =1-(F24)/C24 -> #DIV/0!
A25: 1.49 | B25: Si existe registro en Datos_Contacto, no puede relacionar persona jurídica, es decir que tipo documento no puede ser NIT | C25: =Datos!C17 -> 0 | D25: 0 | E25: 0 | F25: =D25-E25 -> 0 | G25: =1-(F25)/C25 -> #DIV/0!
A26: 1.50 | B26: Si existe registro en Datos_Contacto, el número de documento de quien atendió debe contener solamente caracteres numéricos y ser diferente de "0" | C26: =Datos!C18 -> 0 | D26: 0 | E26: 0 | F26: =D26-E26 -> 0 | G26: =1-(F26)/C26 -> #DIV/0!
A27: 1.51 | B27: Si existe información en Datos_Contacto, el campo de primer nombre quien atendió y primer apellido quien atendió deben estar diligenciados | C27: =Datos!C19 -> 0 | D27: 0 | E27: 0 | F27: =D27-E27 -> 0 | G27: =1-(F27)/C27 -> #DIV/0!
A28: 1.52 | B28: Si existe información en Datos_Contacto y existe dato de número de celular registrado, debe tener 10 dígitos y sus caracteres deben ser numéricos | C28: =Datos!C20 -> 0 | D28: 0 | E28: 0 | F28: =D28-E28 -> 0 | G28: =1-(F28)/C28 -> #DIV/0!
A29: 1.53 | B29: Si existe información en Datos_Contacto y existe dato de correo electrónico, debe tener una estructura lógica (nombre del usuario@dominio) | C29: =Datos!C21 -> 0 | D29: 0 | E29: 0 | F29: =D29-E29 -> 0 | G29: =1-(F29)/C29 -> #DIV/0!
A30: 1.54 | B30: Si existe información en Datos_Contacto y el campo autoriza notificaciones es verdadero, entonces el campo celular y/o correo electrónico debe estar diligenciado | C30: =Datos!C22 -> 0 | D30: 0 | E30: 0 | F30: =D30-E30 -> 0 | G30: =1-(F30)/C30 -> #DIV/0!
A31: 1.55 | B31: Todo registro en la tabla Datos_Contacto debe tener diligenciado el campo domicilio_notificaciones | C31: =Datos!C19 -> 0 | D31: 0 | E31: 0 | F31: =D31-E31 -> 0 | G31: =1-(F31)/C31 -> #DIV/0!
A32: 1.56 | B32: El campo Direccion de la tabla Datos_Contacto debe contener al menos 7 caracteres | C32: =Datos!C23 -> 0 | D32: 0 | E32: 0 | F32: =D32-E32 -> 0 | G32: =1-(F32)/C32 -> #DIV/0!
A33: 1.60 | B33: Para predios en condicion 9 o 8, en el campo Direccion deben tener diligenciado al menos una de las siguiente siglas AP, BQ, BD, CS, ED, ET, GA, IN, L, LO, MZ, OF, PQ, PN, TO, UN, UR | C33: =Datos!C24 -> 0 | D33: 0 | E33: 0 | F33: =D33-E33 -> 0 | G33: =1-(F33)/C33 -> #DIV/0!
A34: PROMEDIO | G34: Calcular

Sheet 2. Jurídico
A1: CONSISTENCIA LOGICA - BASE CATASTRAL DIRECCIÓN DE GESTIÓN CATASTRAL
B3: DEPARTAMENTO: | C3: NOMBRE CONTROL DE CALIDAD QUE ELABORÓ: | H3: Firma:
B4: MUNICIPIO: | C4: NOMBRE CONTROL DE CALIDAD QUE REVISÓ: | H4: Firma:
C5: FECHA DE VALIDACION: | F5: AAAA/MM/DD
A6: ID | B6: ELEMENTO EVALUADO | C6: Cantidad de Items | D6: Situaciones encontradas | E6: Cantidad Excepciones | F6: Cantidad Errores | G6: % Calidad Item | H6: Observaciones
A7: 2.1 | B7: Que la matrícula Inmobiliaria relacionada efectivamente corresponda un folio de matricula (Longitud entre 1 y 8 caracteres). | C7: =Datos!C10 -> 0 | D7: 0 | E7: 0 | F7: =D7-E7 -> 0 | G7: =1-(F7)/C7 -> #DIV/0!
A8: 2.4 | B8: La fecha de inicio de tenencia relacionada en el derecho debe ser mayor a cero (0) y menor a la fecha de la visita al predio o a la fecha de hoy. | C8: =Datos!C8 -> 0 | D8: 0 | E8: 0 | F8: =D8-E8 -> 0 | G8: =1-(F8)/C8 -> #DIV/0!
A9: 2.5 | B9: Un predio formal debe tener asociado un solo Derecho de tipo "Dominio" | C9: =Datos!C25 -> 0 | D9: 0 | E9: 0 | F9: =D9-E9 -> 0 | G9: =1-(F9)/C9 -> #DIV/0!
A10: 2.6 | B10: Un predio formal con Derecho de tipo "Dominio" debe tener Matricula inmobiliaria | C10: =Datos!C26 -> 0 | D10: 0 | E10: 0 | F10: =D10-E10 -> 0 | G10: =1-(F10)/C10 -> #DIV/0!
A11: 2.7 | B11: Los predios asociados a tipos de derecho de “posesión” deben ser tipo de predios “Privados” | C11: =Datos!C27 -> 0 | D11: 0 | E11: 0 | F11: =D11-E11 -> 0 | G11: =1-(F11)/C11 -> #DIV/0!
A12: 2.8 | B12: Los predios con tipo de predio: Privado no deben estar asociados a derechos de “ocupación” | C12: =Datos!C28 -> 0 | D12: 0 | E12: 0 | F12: =D12-E12 -> 0 | G12: =1-(F12)/C12 -> #DIV/0!
A13: 2.9 | B13: Para los predios asociados a tipo de predio público, el tipo de derecho no puede ser posesión | C13: =Datos!C29 -> 0 | D13: 0 | E13: 0 | F13: =D13-E13 -> 0 | G13: =1-(F13)/C13 -> #DIV/0!
A14: 2.10 | B14: En los predios baldíos y asociados a tipo de derecho dominio, el interesado relacionado debe corresponder a la Nación o Municipio o Agencia Nacional de Tierras | C14: =Datos!C30 -> 0 | D14: 0 | E14: 0 | F14: =D14-E14 -> 0 | G14: =1-(F14)/C14 -> #DIV/0!
A15: 2.11 | B15: Si el predio es catalogado como territorio colectivo, el interesado debe corresponder a algún grupo étnico | C15: =Datos!C31 -> 0 | D15: 0 | E15: 0 | F15: =D15-E15 -> 0 | G15: =1-(F15)/C15 -> #DIV/0!
A16: 2.12 | B16: Para los predios baldíos que el derecho tipo asociado es ocupación, el interesado relacionado no debe ser La Nación o Municipio o Agencia Nacional de Tierras | C16: =Datos!C32 -> 0 | D16: 0 | E16: 0 | F16: =D16-E16 -> 0 | G16: =1-(F16)/C16 -> #DIV/0!
A17: 2.13 | B17: Para los predios asociados a públicos (fiscales, patrimoniales o de uso público) que están relacionados con tipo de derecho dominio, el interesado relacionado debe ser una persona jurídica. | C17: =Datos!C32 -> 0 | D17: 0 | E17: 0 | F17: =D17-E17 -> 0 | G17: =1-(F17)/C17 -> #DIV/0!
A18: 2.16 | B18: Para los predios con folio de matrícula inmobiliaria, la fecha de inicio de tenencia asociada al derecho debe ser mayor o igual a la fecha del título (Documento fuente) | C18: =Datos!C10 -> 0 | D18: 0 | E18: 0 | F18: =D18-E18 -> 0 | G18: =1-(F18)/C18 -> #DIV/0!
A19: 2.17 | B19: Si el predio tiene un valor de folio en sistema antiguo (Mayor a 7 caracteres), el dato de Tiene FMI es falso | C19: =Datos!C33 -> 0 | D19: 0 | E19: 0 | F19: =D19-E19 -> 0 | G19: =1-(F19)/C19 -> #DIV/0!
A20: 2.18 | B20: Si el predio tiene folio de matrícula en la tabla Datos_Predio, entonces debe tener registrada una fecha de documento fuente, tipo de fuente administrativa, numero de fuente administrativa y ente emisor. El valor registrado en fecha de documento fuente no puede ser posterior a la fecha de levantamiento | C20: =Datos!C34 -> 0 | D20: 0 | E20: 0 | F20: =D20-E20 -> 0 | G20: =1-(F20)/C20 -> #DIV/0!
A21: 2.20 | B21: Los interesados de tipo “Persona_Jurídica” deben asociar solamente en tipo de documento NIT o número secuencial (este número solamente se utiliza en el caso de los interesados que no fue posible encontrar su documento de identidad). | C21: =Datos!C35 -> 0 | D21: 0 | E21: 0 | F21: =D21-E21 -> 0 | G21: =1-(F21)/C21 -> #DIV/0!
A22: 2.21 | B22: Los interesados de tipo “Persona_Natural” deben asociar solamente en tipo de documento “Cedula de Ciudadanía” o "Pasaporte" o “Cédula de Extranjería” o “Tarjeta de identidad” o “Registro Civil” o número secuencial (este número solamente se utilizará en el caso de los interesados que no fue posible encontrar su documento de identidad) | C22: =Datos!C36 -> 0 | D22: 0 | E22: 0 | F22: =D22-E22 -> 0 | G22: =1-(F22)/C22 -> #DIV/0!
A23: 2.22 | B23: Si el tipo de documento asociado al interesado es Cédula de ciudadanía” o “Cedula de Extranjería” o “Tarjeta de identidad” o “Registro Civil”, el número de documento de identidad debe ser diferente de “cero” o vacío. La opción de secuencial se usa en el caso de interesados en los cuales no fue posible encontrar documento de identificación, al no existir otra opción | C23: =Datos!C37 -> 0 | D23: 0 | E23: 0 | F23: =D23-E23 -> 0 | G23: =1-(F23)/C23 -> #DIV/0!
A24: 2.23 | B24: Si el tipo de documento del interesado es “NIT”, entonces Interesado.documento_identidad > 0 sin letras ni caracteres especiales exceptuando guion "-", no debe ser secuenciales. Antes del guion solo numérico y después del guion únicamente un entero, entre 0 y 9. | C24: =Datos!C38 -> 0 | D24: 0 | E24: 0 | F24: =D24-E24 -> 0 | G24: =1-(F24)/C24 -> #DIV/0!
A25: 2.24 | B25: El atributo de primer nombre, segundo nombre, primer apellido y segundo apellido en interesado solo será usado para aquellos que correspondan a “Personas naturales” y no debe ser numérico ni contener caracteres especiales | C25: =Datos!C36 -> 0 | D25: 0 | E25: 0 | F25: =D25-E25 -> 0 | G25: =1-(F25)/C25 -> #DIV/0!
A26: 2.25 | B26: El atributo de primer nombre, segundo nombre, primer apellido y segundo apellido no será usado para aquellos que correspondan a “Personas jurídicas”. | C26: =Datos!C35 -> 0 | D26: 0 | E26: 0 | F26: =D26-E26 -> 0 | G26: =1-(F26)/C26 -> #DIV/0!
A27: 2.26 | B27: En las bases catastrales vigentes se pueden encontrar palabras asociadas a “SUC” (Sucesiones ilíquidas) que no deben asociarse en los campos de nombre para personas naturales ni asociar números en sus campos | C27: =Datos!C36 -> 0 | D27: 0 | E27: 0 | F27: =D27-E27 -> 0 | G27: =1-(F27)/C27 -> #DIV/0!
A28: 2.27 | B28: Para los interesados asociados a personas jurídicas, solamente se debe diligenciar el campo de razón social | C28: =Datos!C35 -> 0 | D28: 0 | E28: 0 | F28: =D28-E28 -> 0 | G28: =1-(F28)/C28 -> #DIV/0!
A29: 2.28 | B29: El atributo de Sexo en interesado solo será usado para aquellos que correspondan a Personas naturales. | C29: =Datos!C39 -> 0 | D29: 0 | E29: 0 | F29: =D29-E29 -> 0 | G29: =1-(F29)/C29 -> #DIV/0!
A30: 2.29 | B30: Los interesados relacionados a Personas Naturales, en los campos respectivos para identificar su nombre, no se debe asociar personerías Jurídicas | C30: =Datos!C36 -> 0 | D30: 0 | E30: 0 | F30: =D30-E30 -> 0 | G30: =1-(F30)/C30 -> #DIV/0!
A31: 2.30 | B31: Si la agrupación de interesados de un predio está conformada por personas naturales y jurídicas, el tipo de agrupación debe ser Grupo_Mixto | C31: =Datos!C40 -> 0 | D31: 0 | E31: 0 | F31: =D31-E31 -> 0 | G31: =1-(F31)/C31 -> #DIV/0!
A32: 2.32 | B32: Si la agrupación de interesados de un predio está conformada por personas naturales, el tipo de agrupación debe ser Grupo_Civil | C32: =Datos!C39 -> 0 | D32: 0 | E32: 0 | F32: =D32-E32 -> 0 | G32: =1-(F32)/C32 -> #DIV/0!
A33: 2.33 | B33: Si la agrupación de interesados de un predio está conformada por personas jurídicas el tipo de agrupación debe ser Grupo_Empresarial | C33: =Datos!C39 -> 0 | D33: 0 | E33: 0 | F33: =D33-E33 -> 0 | G33: =1-(F33)/C33 -> #DIV/0!
A34: 2.34 | B34: Si el tipo de Fuente Administrativa es Escritura Publica o Sentencia Judicial o Acto Administrativo, no puede estar asociado a un Documento Privado | C34: =Datos!C41 -> 0 | D34: 0 | E34: 0 | F34: =D34-E34 -> 0 | G34: =1-(F34)/C34 -> #DIV/0!
A35: 2.35 | B35: El registro de un dato en ente emisor, numero de fuente y fecha de documento debe ser congruente con el tipo de fuente administrativa asignado. | C35: =Datos!C42 -> 0 | D35: 0 | E35: 0 | F35: =D35-E35 -> 0 | G35: =1-(F35)/C35 -> #DIV/0!
A36: 2.36 | B36: El ente emisor debe corresponder al tipo de fuente administrativa diligenciado. | C36: =Datos!C43 -> 0 | D36: 0 | E36: 0 | F36: =D36-E36 -> 0 | G36: =1-(F36)/C36 -> #DIV/0!
A37: 2.37 | B37: En caso de contar con el contacto de interesado, debe tener registrado departamento y municipio | C37: =Datos!C39 -> 0 | D37: 0 | E37: 0 | F37: =D37-E37 -> 0 | G37: =1-(F37)/C37 -> #DIV/0!
A38: 2.38 | B38: Todo predio debe tener asociado un interesado o agrupación de interesados. | C38: =Datos!C9 -> 0 | D38: 0 | E38: 0 | F38: =D38-E38 -> 0 | G38: =1-(F38)/C38 -> #DIV/0!
A39: 2.39 | B39: Para los interesados que sus nombres y apellidos o razón social son iguales, y presentan diferente número de documento, debe verificarse (Excepción Homónimos). (mismo nombre de propietario, diferente cedula) | C39: =Datos!C39 -> 0 | D39: 0 | E39: 0 | F39: =D39-E39 -> 0 | G39: =1-(F39)/C39 -> #DIV/0!
A40: 2.40 | B40: Para los interesados con igual número de documento, la información relacionada en nombres y apellidos o razón social debe ser igual para todos los registros (misma cédula, diferente propietario) y no deben existir registros de interesados repetidos | C40: =Datos!C39 -> 0 | D40: 0 | E40: 0 | F40: =D40-E40 -> 0 | G40: =1-(F40)/C40 -> #DIV/0!
A41: 2.41 | B41: Los predios informales debe registrar el mismo derecho en los campos a diligenciar y no debe registrar 'Dominio' | C41: =Datos!C44 -> 0 | D41: 0 | E41: 0 | F41: =D41-E41 -> 0 | G41: =1-(F41)/C41 -> #DIV/0!
...

Sheet 3. Fisico
A1: CONSISTENCIA LOGICA - BASE CATASTRAL DIRECCIÓN DE GESTIÓN CATASTRAL
B3: DEPARTAMENTO: | C3: NOMBRE CONTROL DE CALIDAD QUE ELABORÓ: | H3: Firma:
B4: MUNICIPIO: | C4: NOMBRE CONTROL DE CALIDAD QUE REVISÓ: | H4: Firma:
C5: FECHA DE VALIDACION: | F5: AAAA/MM/DD
A6: ID | B6: ELEMENTO EVALUADO | C6: Cantidad de Items | D6: Situaciones encontradas | E6: Cantidad Excepciones | F6: Cantidad Errores | G6: % Calidad Item | H6: Observaciones
A7: 3.1 | B7: Los predios asociados a condiciones de propiedad PH Unidad Predial deben tener asociada una construcción, exceptuando los parqueaderos o garajes descubiertos o unidades de PH no construidas. | C7: =Datos!C45 -> 0 | D7: 0 | E7: 0 | F7: =D7-E7 -> 0 | G7: =1-(F7)/C7 -> #DIV/0!
A8: 3.3 | B8: Para las unidades asociadas a predios en PH y condominio, las unidades convencionales calificadas deben relacionar usos establecidos específicamente para PH. | C8: =Datos!C46 -> 0 | D8: 0 | E8: 0 | F8: =D8-E8 -> 0 | G8: =1-(F8)/C8 -> #DIV/0!
A9: 3.4 | B9: Para las unidades asociadas a predios con condición de propiedad diferente a PH o condominio, las unidades convencionales calificadas deben relacionar usos diferentes a PH. | C9: =Datos!C47 -> 0 | D9: 0 | E9: 0 | F9: =D9-E9 -> 0 | G9: =1-(F9)/C9 -> #DIV/0!
A10: 3.6 | B10: No deben haber poligonos de terreno menores a 5 m² | C10: =Datos!C48 -> 0 | D10: 0 | E10: 0 | F10: =D10-E10 -> 0 | G10: =1-(F10)/C10 -> #DIV/0!
A11: 3.7 | B11: Cada polígono de terreno o de unidad de construccion en PH debe estar asociado a un registro de Datos_Predio. | C11: =Datos!C49 -> 0 | D11: 0 | E11: 0 | F11: =D11-E11 -> 0 | G11: =1-(F11)/C11 -> #DIV/0!
A12: 3.8 | B12: Para el terreno, el dato area_terreno diligenciado y área calculada de la geometría del polígono debe ser igual. | C12: =Datos!C48 -> 0 | D12: 0 | E12: 0 | F12: =D12-E12 -> 0 | G12: =1-(F12)/C12 -> #DIV/0!
A13: 3.9 | B13: El identificador es la variable que unifica unidades de construcción con: usos de construcción, el tipo de dominio, tipo de construcción, tipo de unidad de construcción, tipo de planta, total habitaciones, total baños, total locales, total pisos de la unidad, año de construcción y calificación de iguales características. Además, debe existir una continuidad en la asignación alfabética del identificador, siempre empezando por la letra A a la Z y en caso de existir más unidades se reinicia en AA, AB y así sucesivamente. | C13: =Datos!C50 -> 0 | D13: 0 | E13: 0 | F13: =D13-E13 -> 0 | G13: =1-(F13)/C13 -> #DIV/0!
A14: 3.17 | B14: La planta de ubicación de la unidad de construcción no puede ser cero (0) ni negativa. | C14: =Datos!C50 -> 0 | D14: 0 | E14: 0 | F14: =D14-E14 -> 0 | G14: =1-(F14)/C14 -> #DIV/0!
A15: 3.20 | B15: Los predios con destinación económica habitacional deben tener minimo una unidad de tipo residencial y esta(s) deben ser predominantes en área construidas respecto a las demás | C15: =Datos!C51 -> 0 | D15: 0 | E15: 0 | F15: =D15-E15 -> 0 | G15: =1-(F15)/C15 -> #DIV/0!
A16: 3.21 | B16: Los predios con destinación económica comercial deben tener minimo una unidad de tipo comercial y esta(s) deben ser predominantes en área construidas respecto a las demás | C16: =Datos!C52 -> 0 | D16: 0 | E16: 0 | F16: =D16-E16 -> 0 | G16: =1-(F16)/C16 -> #DIV/0!
A17: 3.22 | B17: Los predios con destinación económica industrial deben tener minimo una unidad de tipo industrial y esta(s) deben ser predominantes en área construidas respecto a las demás | C17: =Datos!C53 -> 0 | D17: 0 | E17: 0 | F17: =D17-E17 -> 0 | G17: =1-(F17)/C17 -> #DIV/0!
A18: 3.25 | B18: La unidad de construcción debe tener asociado un uso | C18: =Datos!C54 -> 0 | D18: 0 | E18: 0 | F18: =D18-E18 -> 0 | G18: =1-(F18)/C18 -> #DIV/0!
A19: 3.30 | B19: El año de construcción de la unidad de construcción debe estar diligenciado y debe ser menor o igual a la fecha de visita | C19: =Datos!C54 -> 0 | D19: 0 | E19: 0 | F19: =D19-E19 -> 0 | G19: =1-(F19)/C19 -> #DIV/0!
A20: 3.33 | B20: La sumatoria de las areas de los poligonos de unidad de construcción que compartan numero predial, tipo de construcción e identificador, debe ser igual al campo "construccion area" de la tabla Unidad de construcción | C20: =Datos!C50 -> 0 | D20: 0 | E20: 0 | F20: =D20-E20 -> 0 | G20: =1-(F20)/C20 -> #DIV/0!
A21: 3.36 | B21: En las construcciones, el campo "numero_pisos" no debe ser 0. | C21: =Datos!C50 -> 0 | D21: 0 | E21: 0 | F21: =D21-E21 -> 0 | G21: =1-(F21)/C21 -> #DIV/0!
A22: PROMEDIO | G22: Calcular

Sheet 4. Economico
A1: CONSISTENCIA LOGICA - BASE CATASTRAL DIRECCIÓN DE GESTIÓN CATASTRAL
B3: DEPARTAMENTO: | C3: NOMBRE CONTROL DE CALIDAD QUE ELABORÓ: | H3: Firma:
B4: MUNICIPIO: | C4: NOMBRE CONTROL DE CALIDAD QUE REVISÓ: | H4: Firma:
C5: FECHA DE VALIDACION: | F5: AAAA/MM/DD
A6: ID | B6: ELEMENTO EVALUADO | C6: Cantidad de Items | D6: Situaciones encontradas | E6: Cantidad Excepciones | F6: Cantidad Errores | G6: % Calidad Item | H6: Observaciones
A7: 4.1 | B7: Si en la unidad de construcción, el tipo de construcción es convencional, entonces debe relacionar una calificación en la tabla tipología tipo o calificación convencional | C7: =Datos!C56 -> 0 | D7: 0 | E7: 0 | F7: =D7-E7 -> 0 | G7: =1-(F7)/C7 -> #DIV/0!
A8: 4.2 | B8: Si en la unidad de construcción, el tipo de construcción es no convencional, entonces debe relacionar una calificación en la tabla de calificación no convencional y debe corresponder a los dominios de Anexo tipo para cada uso (anexos) correspondiente. En caso de que el anexo no tenga ningún tipo de anexo asociado, se debe reportar. | C8: =Datos!C57 -> 0 | D8: 0 | E8: 0 | F8: =D8-E8 -> 0 | G8: =1-(F8)/C8 -> #DIV/0!
A9: PROMEDIO | G9: Calcular

Sheet Resumen
A1: CONSISTENCIA LOGICA - BASE CATASTRAL DIRECCIÓN DE GESTIÓN CATASTRAL
B3: DEPARTAMENTO: | C3: NOMBRE CONTROL DE CALIDAD QUE ELABORÓ: | H3: Firma:
B4: MUNICIPIO: | C4: NOMBRE CONTROL DE CALIDAD QUE REVISÓ: | H4: Firma:
C5: FECHA DE VALIDACION: | F5: AAAA/MM/DD
A6: Item | B6: Grupo(s) | C6: Cantidad Errores | E6: % Calidad Componente | G6: Observaciones
A8: 0 | B8: Estructura | C8: =SUM('0. Estructura'!F7:G8) -> 0 | E8: N/A
A9: 1 | B9: Administrativo | C9: =SUM('1. Administrativo'!F7:F33) -> 0 | E9: ='1. Administrativo'!G34 -> Calcular
A10: 2 | B10: Jurídico | C10: =SUM('2. Jurídico'!F7:F41) -> 0 | E10: ='2. Jurídico'!G42 -> Calcular
A11: 3 | B11: Físico | C11: =SUM('3. Fisico'!F7:F21) -> 0 | E11: ='3. Fisico'!G22 -> Calcular
A12: 4 | B12: Económico | C12: =SUM('4. Economico'!F7:F8) -> 0 | E12: ='4. Economico'!G9 -> Calcular
A13: 5 | B13: Novedades | C13: Digitar | E13: Digitar
A14: TOTAL | C14: =SUM(C8:D12) -> 0 | E14: =AVERAGE(E9:F12) -> #DIV/0!
